Workbook
Name 품목목록: OFFSET('품목요약'!$A$2,0,0,MAX(1,COUNTA('품목요약'!$A:$A)-1),1)

Sheet 계산기
B1: 서원농산 최대 마진 계산기
B2: 노란 칸만 고르거나 적으면 됩니다. 품목·채널은 목록에서 고릅니다.
F3: 계산용 (손대지 않음)
B4: 품목 | D4: ← 품목요약의 품목 (등급·박스 무게별) | F4: 품목 줄 | H4: =IFERROR(MATCH($C$4,'품목요약'!$A:$A,0),0)
B5: 판매 채널 | F5: 채널 줄 | H5: =IFERROR(MATCH($C$5,'설정'!$A$4:$A$11,0),0)
B6: 원가 기준 | D6: 최근 | 7일평균 | 7일최고 | F6: 소매 상한 | H6: =IF(AND($H$4>0,$H$5>0,$C$15>0),$C$15*$C$11*(1-INDEX('설정'!$G$4:$G$11,$H$5)/100),"")
B7: 판매가 (원/박스, 비우면 권장가) | F7: 가락 상한 | H7: =IF(AND($H$4>0,$H$5>0,$C$14>0),$C$14*$C$11*(1+INDEX('설정'!$H$4:$H$11,$H$5)/100),"")
B8: 판매 수량 (박스) | C8: 10 | F8: 상한 기준 | H8: =IF($H$5>0,INDEX('설정'!$F$4:$F$11,$H$5),"")
B10: 품목 정보
B11: 박스 무게(kg) | C11: =IF($H$4>0,INDEX('품목요약'!$D:$D,$H$4),"")
B12: 최근 경매일 | C12: =IF($H$4>0,INDEX('품목요약'!$E:$E,$H$4),"")
B13: 원가 (박스당 낙찰 단가) | C13: =IF($H$4=0,"",IF($C$6="최근",INDEX('품목요약'!$F:$F,$H$4),IF($C$6="7일최고",INDEX('품목요약'!$H:$H,$H$4),INDEX('품목요약'!$G:$G,$H$4)))) | D13: 원가 기준에 따라 최근·7일평균·7일최고
B14: 가락시장 7일 kg당 평균 | C14: =IF($H$4>0,N(INDEX('품목요약'!$N:$N,$H$4)),0) | D14: 공영도매시장 경락가 중 가락시장 (특·상만)
B15: 지역 소매 kg당 가운데값 | C15: =IF($H$4>0,N(INDEX('품목요약'!$P:$P,$H$4)),0) | D15: KAMIS 지역별 소매가
B17: 판매 채널 비용
B18: 수수료율 | C18: =IF($H$5>0,INDEX('설정'!$B$4:$B$11,$H$5)/100,0)
B19: 부대비 (택배+포장+기타) | C19: =IF($H$5>0,INDEX('설정'!$C$4:$C$11,$H$5)+INDEX('설정'!$D$4:$D$11,$H$5)+INDEX('설정'!$E$4:$E$11,$H$5),0)
B21: 결과
B22: 손익분기가 | C22: =IF($C$13="","",($C$13+$C$19)/(1-$C$18)) | D22: 이 값보다 싸게 팔면 손해
B23: 최소 마진가 (하한) | C23: =IF($C$22="","",$C$22*(1+IF($H$5>0,INDEX('설정'!$I$4:$I$11,$H$5),0)/100)) | D23: 최소 마진을 지키는 가장 낮은 값
B24: 상한가 | C24: =IF($C$13="","",IF($H$8="소매",IF($H$6<>"",$H$6,$H$7),IF($H$7<>"",$H$7,$H$6))) | D24: 이보다 비싸면 소비자가 마트·시장을 택할 값
B25: 상한 기준 | C25: =IF($C$24="","자료 없음",IF($H$8="소매",IF($H$6<>"","소매","가락(대신)"),IF($H$7<>"","가락","소매(대신)")))
B26: 최대 마진 (상한가에 팔 때, 박스당) | C26: =IF(OR($C$24="",$C$13=""),"",$C$24*(1-$C$18)-$C$13-$C$19) | D26: 이 품목·채널에서 낼 수 있는 가장 큰 마진
B27: 최대 마진율 | C27: =IF($C$26="","",$C$26/$C$24)
B28: 권장가 | C28: =IF($C$23="","",IF($C$24="",$C$23,IF($C$24>$C$23,($C$23+$C$24)/2,$C$23))) | D28: 하한과 상한의 가운데
B29: 권장가 마진 (박스당) | C29: =IF($C$28="","",$C$28*(1-$C$18)-$C$13-$C$19)
B31: 내 판매가로 계산
B32: 적용 판매가 | C32: =IF(N($C$7)>0,$C$7,$C$28) | D32: 판매가를 비우면 권장가
B33: 박스당 마진 | C33: =IF(OR($C$32="",$C$13=""),"",$C$32*(1-$C$18)-$C$13-$C$19)
B34: 마진율 | C34: =IF($C$33="","",$C$33/$C$32)
B35: 총 마진 (× 판매 수량) | C35: =IF($C$33="","",$C$33*N($C$8))
B36: 최대 마진과의 차이 (박스당) | C36: =IF(OR($C$33="",$C$26=""),"",$C$33-$C$26) | D36: 0 에 가까울수록 최대 마진에 가깝게 판 것
B39: 가격별 마진 (그래프 시트의 '가격별 마진' 그래프)
B40: 판매가 | C40: 박스당 마진 | D40: 마진율
B41: =IF($C$22="",NA(),ROUND(($C$22*0.9)+((IF($C$24="",$C$22*1.6,MAX($C$24,$C$22)*1.1))-($C$22*0.9))*0/20,-1)) | C41: =IF($C$22="",NA(),B41*(1-$C$18)-$C$13-$C$19) | D41: =IF($C$22="",NA(),C41/B41)
B42: =IF($C$22="",NA(),ROUND(($C$22*0.9)+((IF($C$24="",$C$22*1.6,MAX($C$24,$C$22)*1.1))-($C$22*0.9))*1/20,-1)) | C42: =IF($C$22="",NA(),B42*(1-$C$18)-$C$13-$C$19) | D42: =IF($C$22="",NA(),C42/B42)
B43: =IF($C$22="",NA(),ROUND(($C$22*0.9)+((IF($C$24="",$C$22*1.6,MAX($C$24,$C$22)*1.1))-($C$22*0.9))*2/20,-1)) | C43: =IF($C$22="",NA(),B43*(1-$C$18)-$C$13-$C$19) | D43: =IF($C$22="",NA(),C43/B43)
B44: =IF($C$22="",NA(),ROUND(($C$22*0.9)+((IF($C$24="",$C$22*1.6,MAX($C$24,$C$22)*1.1))-($C$22*0.9))*3/20,-1)) | C44: =IF($C$22="",NA(),B44*(1-$C$18)-$C$13-$C$19) | D44: =IF($C$22="",NA(),C44/B44)
B45: =IF($C$22="",NA(),ROUND(($C$22*0.9)+((IF($C$24="",$C$22*1.6,MAX($C$24,$C$22)*1.1))-($C$22*0.9))*4/20,-1)) | C45: =IF($C$22="",NA(),B45*(1-$C$18)-$C$13-$C$19) | D45: =IF($C$22="",NA(),C45/B45)
B46: =IF($C$22="",NA(),ROUND(($C$22*0.9)+((IF($C$24="",$C$22*1.6,MAX($C$24,$C$22)*1.1))-($C$22*0.9))*5/20,-1)) | C46: =IF($C$22="",NA(),B46*(1-$C$18)-$C$13-$C$19) | D46: =IF($C$22="",NA(),C46/B46)
...

Sheet 그래프
A1: 그래프 — 계산기에서 품목·채널을 바꾸면 함께 바뀝니다

Sheet 품목요약
A1: 품목 | B1: 품목군 | C1: 등급 | D1: 박스kg | E1: 최근 경매일 | F1: 최근 단가(박스) | G1: 7일 평균(박스) | H1: 7일 최고(박스) | I1: 기간 평균(박스) | J1: 기간 최저 단가 | K1: 기간 최고 단가 | L1: 총 낙찰 수량 | M1: 총 낙찰 금액 | N1: 가락 7일 kg당 | O1: 전국 7일 kg당 | P1: 소매 kg당(가운데) | Q1: 가락 박스 환산 | R1: 가락보다 싸게 산 금액 | S1: 원가(기준) | T1: ='설정'!$A$4&" 상한가" | U1: ='설정'!$A$4&" 최대 마진" | V1: ='설정'!$A$4&" 마진율" | W1: ='설정'!$A$5&" 상한가" | X1: ='설정'!$A$5&" 최대 마진" | Y1: ='설정'!$A$5&" 마진율" | Z1: ='설정'!$A$6&" 상한가" | AA1: ='설정'!$A$6&" 최대 마진" | AB1: ='설정'!$A$6&" 마진율"

Sheet 추이
A1: 선택한 품목의 날짜별 추이 (계산기 C4 의 품목) | F1: 품목 | G1: ='계산기'!$C$4
A2: 날짜 | B2: 서원 낙찰 평균(박스) | C2: 가락 평균(박스 환산) | D2: 전국 평균(박스 환산) | E2: 소매 기준 상한(박스) | F2: 가락보다 싸게 산 금액 | G2: 그날 낙찰 수량
A3: =IFERROR(MAX('일별데이터'!$A:$A),TODAY())-39 | B3: =IFERROR(SUMIFS('일별데이터'!$I:$I,'일별데이터'!$B:$B,$G$1,'일별데이터'!$A:$A,$A3)/SUMIFS('일별데이터'!$E:$E,'일별데이터'!$B:$B,$G$1,'일별데이터'!$A:$A,$A3),NA()) | C3: =IFERROR(AVERAGEIFS('일별데이터'!$J:$J,'일별데이터'!$B:$B,$G$1,'일별데이터'!$A:$A,$A3)*'계산기'!$C$11,NA()) | D3: =IFERROR(AVERAGEIFS('일별데이터'!$N:$N,'일별데이터'!$B:$B,$G$1,'일별데이터'!$A:$A,$A3)*'계산기'!$C$11,NA()) | E3: =IFERROR(AVERAGEIFS('일별데이터'!$O:$O,'일별데이터'!$B:$B,$G$1,'일별데이터'!$A:$A,$A3)*'계산기'!$C$11*(1-IF('계산기'!$H$5>0,INDEX('설정'!$G$4:$G$11,'계산기'!$H$5),0)/100),NA()) | F3: =IFERROR(C3-B3,NA()) | G3: =SUMIFS('일별데이터'!$E:$E,'일별데이터'!$B:$B,$G$1,'일별데이터'!$A:$A,$A3)
A4: =IFERROR(MAX('일별데이터'!$A:$A),TODAY())-38 | B4: =IFERROR(SUMIFS('일별데이터'!$I:$I,'일별데이터'!$B:$B,$G$1,'일별데이터'!$A:$A,$A4)/SUMIFS('일별데이터'!$E:$E,'일별데이터'!$B:$B,$G$1,'일별데이터'!$A:$A,$A4),NA()) | C4: =IFERROR(AVERAGEIFS('일별데이터'!$J:$J,'일별데이터'!$B:$B,$G$1,'일별데이터'!$A:$A,$A4)*'계산기'!$C$11,NA()) | D4: =IFERROR(AVERAGEIFS('일별데이터'!$N:$N,'일별데이터'!$B:$B,$G$1,'일별데이터'!$A:$A,$A4)*'계산기'!$C$11,NA()) | E4: =IFERROR(AVERAGEIFS('일별데이터'!$O:$O,'일별데이터'!$B:$B,$G$1,'일별데이터'!$A:$A,$A4)*'계산기'!$C$11*(1-IF('계산기'!$H$5>0,INDEX('설정'!$G$4:$G$11,'계산기'!$H$5),0)/100),NA()) | F4: =IFERROR(C4-B4,NA()) | G4: =SUMIFS('일별데이터'!$E:$E,'일별데이터'!$B:$B,$G$1,'일별데이터'!$A:$A,$A4)
A5: =IFERROR(MAX('일별데이터'!$A:$A),TODAY())-37 | B5: =IFERROR(SUMIFS('일별데이터'!$I:$I,'일별데이터'!$B:$B,$G$1,'일별데이터'!$A:$A,$A5)/SUMIFS('일별데이터'!$E:$E,'일별데이터'!$B:$B,$G$1,'일별데이터'!$A:$A,$A5),NA()) | C5: =IFERROR(AVERAGEIFS('일별데이터'!$J:$J,'일별데이터'!$B:$B,$G$1,'일별데이터'!$A:$A,$A5)*'계산기'!$C$11,NA()) | D5: =IFERROR(AVERAGEIFS('일별데이터'!$N:$N,'일별데이터'!$B:$B,$G$1,'일별데이터'!$A:$A,$A5)*'계산기'!$C$11,NA()) | E5: =IFERROR(AVERAGEIFS('일별데이터'!$O:$O,'일별데이터'!$B:$B,$G$1,'일별데이터'!$A:$A,$A5)*'계산기'!$C$11*(1-IF('계산기'!$H$5>0,INDEX('설정'!$G$4:$G$11,'계산기'!$H$5),0)/100),NA()) | F5: =IFERROR(C5-B5,NA()) | G5: =SUMIFS('일별데이터'!$E:$E,'일별데이터'!$B:$B,$G$1,'일별데이터'!$A:$A,$A5)
A6: =IFERROR(MAX('일별데이터'!$A:$A),TODAY())-36 | B6: =IFERROR(SUMIFS('일별데이터'!$I:$I,'일별데이터'!$B:$B,$G$1,'일별데이터'!$A:$A,$A6)/SUMIFS('일별데이터'!$E:$E,'일별데이터'!$B:$B,$G$1,'일별데이터'!$A:$A,$A6),NA()) | C6: =IFERROR(AVERAGEIFS('일별데이터'!$J:$J,'일별데이터'!$B:$B,$G$1,'일별데이터'!$A:$A,$A6)*'계산기'!$C$11,NA()) | D6: =IFERROR(AVERAGEIFS('일별데이터'!$N:$N,'일별데이터'!$B:$B,$G$1,'일별데이터'!$A:$A,$A6)*'계산기'!$C$11,NA()) | E6: =IFERROR(AVERAGEIFS('일별데이터'!$O:$O,'일별데이터'!$B:$B,$G$1,'일별데이터'!$A:$A,$A6)*'계산기'!$C$11*(1-IF('계산기'!$H$5>0,INDEX('설정'!$G$4:$G$11,'계산기'!$H$5),0)/100),NA()) | F6: =IFERROR(C6-B6,NA()) | G6: =SUMIFS('일별데이터'!$E:$E,'일별데이터'!$B:$B,$G$1,'일별데이터'!$A:$A,$A6)
A7: =IFERROR(MAX('일별데이터'!$A:$A),TODAY())-35 | B7: =IFERROR(SUMIFS('일별데이터'!$I:$I,'일별데이터'!$B:$B,$G$1,'일별데이터'!$A:$A,$A7)/SUMIFS('일별데이터'!$E:$E,'일별데이터'!$B:$B,$G$1,'일별데이터'!$A:$A,$A7),NA()) | C7: =IFERROR(AVERAGEIFS('일별데이터'!$J:$J,'일별데이터'!$B:$B,$G$1,'일별데이터'!$A:$A,$A7)*'계산기'!$C$11,NA()) | D7: =IFERROR(AVERAGEIFS('일별데이터'!$N:$N,'일별데이터'!$B:$B,$G$1,'일별데이터'!$A:$A,$A7)*'계산기'!$C$11,NA()) | E7: =IFERROR(AVERAGEIFS('일별데이터'!$O:$O,'일별데이터'!$B:$B,$G$1,'일별데이터'!$A:$A,$A7)*'계산기'!$C$11*(1-IF('계산기'!$H$5>0,INDEX('설정'!$G$4:$G$11,'계산기'!$H$5),0)/100),NA()) | F7: =IFERROR(C7-B7,NA()) | G7: =SUMIFS('일별데이터'!$E:$E,'일별데이터'!$B:$B,$G$1,'일별데이터'!$A:$A,$A7)
A8: =IFERROR(MAX('일별데이터'!$A:$A),TODAY())-34 | B8: =IFERROR(SUMIFS('일별데이터'!$I:$I,'일별데이터'!$B:$B,$G$1,'일별데이터'!$A:$A,$A8)/SUMIFS('일별데이터'!$E:$E,'일별데이터'!$B:$B,$G$1,'일별데이터'!$A:$A,$A8),NA()) | C8: =IFERROR(AVERAGEIFS('일별데이터'!$J:$J,'일별데이터'!$B:$B,$G$1,'일별데이터'!$A:$A,$A8)*'계산기'!$C$11,NA()) | D8: =IFERROR(AVERAGEIFS('일별데이터'!$N:$N,'일별데이터'!$B:$B,$G$1,'일별데이터'!$A:$A,$A8)*'계산기'!$C$11,NA()) | E8: =IFERROR(AVERAGEIFS('일별데이터'!$O:$O,'일별데이터'!$B:$B,$G$1,'일별데이터'!$A:$A,$A8)*'계산기'!$C$11*(1-IF('계산기'!$H$5>0,INDEX('설정'!$G$4:$G$11,'계산기'!$H$5),0)/100),NA()) | F8: =IFERROR(C8-B8,NA()) | G8: =SUMIFS('일별데이터'!$E:$E,'일별데이터'!$B:$B,$G$1,'일별데이터'!$A:$A,$A8)
A9: =IFERROR(MAX('일별데이터'!$A:$A),TODAY())-33 | B9: =IFERROR(SUMIFS('일별데이터'!$I:$I,'일별데이터'!$B:$B,$G$1,'일별데이터'!$A:$A,$A9)/SUMIFS('일별데이터'!$E:$E,'일별데이터'!$B:$B,$G$1,'일별데이터'!$A:$A,$A9),NA()) | C9: =IFERROR(AVERAGEIFS('일별데이터'!$J:$J,'일별데이터'!$B:$B,$G$1,'일별데이터'!$A:$A,$A9)*'계산기'!$C$11,NA()) | D9: =IFERROR(AVERAGEIFS('일별데이터'!$N:$N,'일별데이터'!$B:$B,$G$1,'일별데이터'!$A:$A,$A9)*'계산기'!$C$11,NA()) | E9: =IFERROR(AVERAGEIFS('일별데이터'!$O:$O,'일별데이터'!$B:$B,$G$1,'일별데이터'!$A:$A,$A9)*'계산기'!$C$11*(1-IF('계산기'!$H$5>0,INDEX('설정'!$G$4:$G$11,'계산기'!$H$5),0)/100),NA()) | F9: =IFERROR(C9-B9,NA()) | G9: =SUMIFS('일별데이터'!$E:$E,'일별데이터'!$B:$B,$G$1,'일별데이터'!$A:$A,$A9)
A10: =IFERROR(MAX('일별데이터'!$A:$A),TODAY())-32 | B10: =IFERROR(SUMIFS('일별데이터'!$I:$I,'일별데이터'!$B:$B,$G$1,'일별데이터'!$A:$A,$A10)/SUMIFS('일별데이터'!$E:$E,'일별데이터'!$B:$B,$G$1,'일별데이터'!$A:$A,$A10),NA()) | C10: =IFERROR(AVERAGEIFS('일별데이터'!$J:$J,'일별데이터'!$B:$B,$G$1,'일별데이터'!$A:$A,$A10)*'계산기'!$C$11,NA()) | D10: =IFERROR(AVERAGEIFS('일별데이터'!$N:$N,'일별데이터'!$B:$B,$G$1,'일별데이터'!$A:$A,$A10)*'계산기'!$C$11,NA()) | E10: =IFERROR(AVERAGEIFS('일별데이터'!$O:$O,'일별데이터'!$B:$B,$G$1,'일별데이터'!$A:$A,$A10)*'계산기'!$C$11*(1-IF('계산기'!$H$5>0,INDEX('설정'!$G$4:$G$11,'계산기'!$H$5),0)/100),NA()) | F10: =IFERROR(C10-B10,NA()) | G10: =SUMIFS('일별데이터'!$E:$E,'일별데이터'!$B:$B,$G$1,'일별데이터'!$A:$A,$A10)
A11: =IFERROR(MAX('일별데이터'!$A:$A),TODAY())-31 | B11: =IFERROR(SUMIFS('일별데이터'!$I:$I,'일별데이터'!$B:$B,$G$1,'일별데이터'!$A:$A,$A11)/SUMIFS('일별데이터'!$E:$E,'일별데이터'!$B:$B,$G$1,'일별데이터'!$A:$A,$A11),NA()) | C11: =IFERROR(AVERAGEIFS('일별데이터'!$J:$J,'일별데이터'!$B:$B,$G$1,'일별데이터'!$A:$A,$A11)*'계산기'!$C$11,NA()) | D11: =IFERROR(AVERAGEIFS('일별데이터'!$N:$N,'일별데이터'!$B:$B,$G$1,'일별데이터'!$A:$A,$A11)*'계산기'!$C$11,NA()) | E11: =IFERROR(AVERAGEIFS('일별데이터'!$O:$O,'일별데이터'!$B:$B,$G$1,'일별데이터'!$A:$A,$A11)*'계산기'!$C$11*(1-IF('계산기'!$H$5>0,INDEX('설정'!$G$4:$G$11,'계산기'!$H$5),0)/100),NA()) | F11: =IFERROR(C11-B11,NA()) | G11: =SUMIFS('일별데이터'!$E:$E,'일별데이터'!$B:$B,$G$1,'일별데이터'!$A:$A,$A11)
A12: =IFERROR(MAX('일별데이터'!$A:$A),TODAY())-30 | B12: =IFERROR(SUMIFS('일별데이터'!$I:$I,'일별데이터'!$B:$B,$G$1,'일별데이터'!$A:$A,$A12)/SUMIFS('일별데이터'!$E:$E,'일별데이터'!$B:$B,$G$1,'일별데이터'!$A:$A,$A12),NA()) | C12: =IFERROR(AVERAGEIFS('일별데이터'!$J:$J,'일별데이터'!$B:$B,$G$1,'일별데이터'!$A:$A,$A12)*'계산기'!$C$11,NA()) | D12: =IFERROR(AVERAGEIFS('일별데이터'!$N:$N,'일별데이터'!$B:$B,$G$1,'일별데이터'!$A:$A,$A12)*'계산기'!$C$11,NA()) | E12: =IFERROR(AVERAGEIFS('일별데이터'!$O:$O,'일별데이터'!$B:$B,$G$1,'일별데이터'!$A:$A,$A12)*'계산기'!$C$11*(1-IF('계산기'!$H$5>0,INDEX('설정'!$G$4:$G$11,'계산기'!$H$5),0)/100),NA()) | F12: =IFERROR(C12-B12,NA()) | G12: =SUMIFS('일별데이터'!$E:$E,'일별데이터'!$B:$B,$G$1,'일별데이터'!$A:$A,$A12)
A13: =IFERROR(MAX('일별데이터'!$A:$A),TODAY())-29 | B13: =IFERROR(SUMIFS('일별데이터'!$I:$I,'일별데이터'!$B:$B,$G$1,'일별데이터'!$A:$A,$A13)/SUMIFS('일별데이터'!$E:$E,'일별데이터'!$B:$B,$G$1,'일별데이터'!$A:$A,$A13),NA()) | C13: =IFERROR(AVERAGEIFS('일별데이터'!$J:$J,'일별데이터'!$B:$B,$G$1,'일별데이터'!$A:$A,$A13)*'계산기'!$C$11,NA()) | D13: =IFERROR(AVERAGEIFS('일별데이터'!$N:$N,'일별데이터'!$B:$B,$G$1,'일별데이터'!$A:$A,$A13)*'계산기'!$C$11,NA()) | E13: =IFERROR(AVERAGEIFS('일별데이터'!$O:$O,'일별데이터'!$B:$B,$G$1,'일별데이터'!$A:$A,$A13)*'계산기'!$C$11*(1-IF('계산기'!$H$5>0,INDEX('설정'!$G$4:$G$11,'계산기'!$H$5),0)/100),NA()) | F13: =IFERROR(C13-B13,NA()) | G13: =SUMIFS('일별데이터'!$E:$E,'일별데이터'!$B:$B,$G$1,'일별데이터'!$A:$A,$A13)
A14: =IFERROR(MAX('일별데이터'!$A:$A),TODAY())-28 | B14: =IFERROR(SUMIFS('일별데이터'!$I:$I,'일별데이터'!$B:$B,$G$1,'일별데이터'!$A:$A,$A14)/SUMIFS('일별데이터'!$E:$E,'일별데이터'!$B:$B,$G$1,'일별데이터'!$A:$A,$A14),NA()) | C14: =IFERROR(AVERAGEIFS('일별데이터'!$J:$J,'일별데이터'!$B:$B,$G$1,'일별데이터'!$A:$A,$A14)*'계산기'!$C$11,NA()) | D14: =IFERROR(AVERAGEIFS('일별데이터'!$N:$N,'일별데이터'!$B:$B,$G$1,'일별데이터'!$A:$A,$A14)*'계산기'!$C$11,NA()) | E14: =IFERROR(AVERAGEIFS('일별데이터'!$O:$O,'일별데이터'!$B:$B,$G$1,'일별데이터'!$A:$A,$A14)*'계산기'!$C$11*(1-IF('계산기'!$H$5>0,INDEX('설정'!$G$4:$G$11,'계산기'!$H$5),0)/100),NA()) | F14: =IFERROR(C14-B14,NA()) | G14: =SUMIFS('일별데이터'!$E:$E,'일별데이터'!$B:$B,$G$1,'일별데이터'!$A:$A,$A14)
A15: =IFERROR(MAX('일별데이터'!$A:$A),TODAY())-27 | B15: =IFERROR(SUMIFS('일별데이터'!$I:$I,'일별데이터'!$B:$B,$G$1,'일별데이터'!$A:$A,$A15)/SUMIFS('일별데이터'!$E:$E,'일별데이터'!$B:$B,$G$1,'일별데이터'!$A:$A,$A15),NA()) | C15: =IFERROR(AVERAGEIFS('일별데이터'!$J:$J,'일별데이터'!$B:$B,$G$1,'일별데이터'!$A:$A,$A15)*'계산기'!$C$11,NA()) | D15: =IFERROR(AVERAGEIFS('일별데이터'!$N:$N,'일별데이터'!$B:$B,$G$1,'일별데이터'!$A:$A,$A15)*'계산기'!$C$11,NA()) | E15: =IFERROR(AVERAGEIFS('일별데이터'!$O:$O,'일별데이터'!$B:$B,$G$1,'일별데이터'!$A:$A,$A15)*'계산기'!$C$11*(1-IF('계산기'!$H$5>0,INDEX('설정'!$G$4:$G$11,'계산기'!$H$5),0)/100),NA()) | F15: =IFERROR(C15-B15,NA()) | G15: =SUMIFS('일별데이터'!$E:$E,'일별데이터'!$B:$B,$G$1,'일별데이터'!$A:$A,$A15)
A16: =IFERROR(MAX('일별데이터'!$A:$A),TODAY())-26 | B16: =IFERROR(SUMIFS('일별데이터'!$I:$I,'일별데이터'!$B:$B,$G$1,'일별데이터'!$A:$A,$A16)/SUMIFS('일별데이터'!$E:$E,'일별데이터'!$B:$B,$G$1,'일별데이터'!$A:$A,$A16),NA()) | C16: =IFERROR(AVERAGEIFS('일별데이터'!$J:$J,'일별데이터'!$B:$B,$G$1,'일별데이터'!$A:$A,$A16)*'계산기'!$C$11,NA()) | D16: =IFERROR(AVERAGEIFS('일별데이터'!$N:$N,'일별데이터'!$B:$B,$G$1,'일별데이터'!$A:$A,$A16)*'계산기'!$C$11,NA()) | E16: =IFERROR(AVERAGEIFS('일별데이터'!$O:$O,'일별데이터'!$B:$B,$G$1,'일별데이터'!$A:$A,$A16)*'계산기'!$C$11*(1-IF('계산기'!$H$5>0,INDEX('설정'!$G$4:$G$11,'계산기'!$H$5),0)/100),NA()) | F16: =IFERROR(C16-B16,NA()) | G16: =SUMIFS('일별데이터'!$E:$E,'일별데이터'!$B:$B,$G$1,'일별데이터'!$A:$A,$A16)
A17: =IFERROR(MAX('일별데이터'!$A:$A),TODAY())-25 | B17: =IFERROR(SUMIFS('일별데이터'!$I:$I,'일별데이터'!$B:$B,$G$1,'일별데이터'!$A:$A,$A17)/SUMIFS('일별데이터'!$E:$E,'일별데이터'!$B:$B,$G$1,'일별데이터'!$A:$A,$A17),NA()) | C17: =IFERROR(AVERAGEIFS('일별데이터'!$J:$J,'일별데이터'!$B:$B,$G$1,'일별데이터'!$A:$A,$A17)*'계산기'!$C$11,NA()) | D17: =IFERROR(AVERAGEIFS('일별데이터'!$N:$N,'일별데이터'!$B:$B,$G$1,'일별데이터'!$A:$A,$A17)*'계산기'!$C$11,NA()) | E17: =IFERROR(AVERAGEIFS('일별데이터'!$O:$O,'일별데이터'!$B:$B,$G$1,'일별데이터'!$A:$A,$A17)*'계산기'!$C$11*(1-IF('계산기'!$H$5>0,INDEX('설정'!$G$4:$G$11,'계산기'!$H$5),0)/100),NA()) | F17: =IFERROR(C17-B17,NA()) | G17: =SUMIFS('일별데이터'!$E:$E,'일별데이터'!$B:$B,$G$1,'일별데이터'!$A:$A,$A17)
A18: =IFERROR(MAX('일별데이터'!$A:$A),TODAY())-24 | B18: =IFERROR(SUMIFS('일별데이터'!$I:$I,'일별데이터'!$B:$B,$G$1,'일별데이터'!$A:$A,$A18)/SUMIFS('일별데이터'!$E:$E,'일별데이터'!$B:$B,$G$1,'일별데이터'!$A:$A,$A18),NA()) | C18: =IFERROR(AVERAGEIFS('일별데이터'!$J:$J,'일별데이터'!$B:$B,$G$1,'일별데이터'!$A:$A,$A18)*'계산기'!$C$11,NA()) | D18: =IFERROR(AVERAGEIFS('일별데이터'!$N:$N,'일별데이터'!$B:$B,$G$1,'일별데이터'!$A:$A,$A18)*'계산기'!$C$11,NA()) | E18: =IFERROR(AVERAGEIFS('일별데이터'!$O:$O,'일별데이터'!$B:$B,$G$1,'일별데이터'!$A:$A,$A18)*'계산기'!$C$11*(1-IF('계산기'!$H$5>0,INDEX('설정'!$G$4:$G$11,'계산기'!$H$5),0)/100),NA()) | F18: =IFERROR(C18-B18,NA()) | G18: =SUMIFS('일별데이터'!$E:$E,'일별데이터'!$B:$B,$G$1,'일별데이터'!$A:$A,$A18)
A19: =IFERROR(MAX('일별데이터'!$A:$A),TODAY())-23 | B19: =IFERROR(SUMIFS('일별데이터'!$I:$I,'일별데이터'!$B:$B,$G$1,'일별데이터'!$A:$A,$A19)/SUMIFS('일별데이터'!$E:$E,'일별데이터'!$B:$B,$G$1,'일별데이터'!$A:$A,$A19),NA()) | C19: =IFERROR(AVERAGEIFS('일별데이터'!$J:$J,'일별데이터'!$B:$B,$G$1,'일별데이터'!$A:$A,$A19)*'계산기'!$C$11,NA()) | D19: =IFERROR(AVERAGEIFS('일별데이터'!$N:$N,'일별데이터'!$B:$B,$G$1,'일별데이터'!$A:$A,$A19)*'계산기'!$C$11,NA()) | E19: =IFERROR(AVERAGEIFS('일별데이터'!$O:$O,'일별데이터'!$B:$B,$G$1,'일별데이터'!$A:$A,$A19)*'계산기'!$C$11*(1-IF('계산기'!$H$5>0,INDEX('설정'!$G$4:$G$11,'계산기'!$H$5),0)/100),NA()) | F19: =IFERROR(C19-B19,NA()) | G19: =SUMIFS('일별데이터'!$E:$E,'일별데이터'!$B:$B,$G$1,'일별데이터'!$A:$A,$A19)
A20: =IFERROR(MAX('일별데이터'!$A:$A),TODAY())-22 | B20: =IFERROR(SUMIFS('일별데이터'!$I:$I,'일별데이터'!$B:$B,$G$1,'일별데이터'!$A:$A,$A20)/SUMIFS('일별데이터'!$E:$E,'일별데이터'!$B:$B,$G$1,'일별데이터'!$A:$A,$A20),NA()) | C20: =IFERROR(AVERAGEIFS('일별데이터'!$J:$J,'일별데이터'!$B:$B,$G$1,'일별데이터'!$A:$A,$A20)*'계산기'!$C$11,NA()) | D20: =IFERROR(AVERAGEIFS('일별데이터'!$N:$N,'일별데이터'!$B:$B,$G$1,'일별데이터'!$A:$A,$A20)*'계산기'!$C$11,NA()) | E20: =IFERROR(AVERAGEIFS('일별데이터'!$O:$O,'일별데이터'!$B:$B,$G$1,'일별데이터'!$A:$A,$A20)*'계산기'!$C$11*(1-IF('계산기'!$H$5>0,INDEX('설정'!$G$4:$G$11,'계산기'!$H$5),0)/100),NA()) | F20: =IFERROR(C20-B20,NA()) | G20: =SUMIFS('일별데이터'!$E:$E,'일별데이터'!$B:$B,$G$1,'일별데이터'!$A:$A,$A20)
A21: =IFERROR(MAX('일별데이터'!$A:$A),TODAY())-21 | B21: =IFERROR(SUMIFS('일별데이터'!$I:$I,'일별데이터'!$B:$B,$G$1,'일별데이터'!$A:$A,$A21)/SUMIFS('일별데이터'!$E:$E,'일별데이터'!$B:$B,$G$1,'일별데이터'!$A:$A,$A21),NA()) | C21: =IFERROR(AVERAGEIFS('일별데이터'!$J:$J,'일별데이터'!$B:$B,$G$1,'일별데이터'!$A:$A,$A21)*'계산기'!$C$11,NA()) | D21: =IFERROR(AVERAGEIFS('일별데이터'!$N:$N,'일별데이터'!$B:$B,$G$1,'일별데이터'!$A:$A,$A21)*'계산기'!$C$11,NA()) | E21: =IFERROR(AVERAGEIFS('일별데이터'!$O:$O,'일별데이터'!$B:$B,$G$1,'일별데이터'!$A:$A,$A21)*'계산기'!$C$11*(1-IF('계산기'!$H$5>0,INDEX('설정'!$G$4:$G$11,'계산기'!$H$5),0)/100),NA()) | F21: =IFERROR(C21-B21,NA()) | G21: =SUMIFS('일별데이터'!$E:$E,'일별데이터'!$B:$B,$G$1,'일별데이터'!$A:$A,$A21)
A22: =IFERROR(MAX('일별데이터'!$A:$A),TODAY())-20 | B22: =IFERROR(SUMIFS('일별데이터'!$I:$I,'일별데이터'!$B:$B,$G$1,'일별데이터'!$A:$A,$A22)/SUMIFS('일별데이터'!$E:$E,'일별데이터'!$B:$B,$G$1,'일별데이터'!$A:$A,$A22),NA()) | C22: =IFERROR(AVERAGEIFS('일별데이터'!$J:$J,'일별데이터'!$B:$B,$G$1,'일별데이터'!$A:$A,$A22)*'계산기'!$C$11,NA()) | D22: =IFERROR(AVERAGEIFS('일별데이터'!$N:$N,'일별데이터'!$B:$B,$G$1,'일별데이터'!$A:$A,$A22)*'계산기'!$C$11,NA()) | E22: =IFERROR(AVERAGEIFS('일별데이터'!$O:$O,'일별데이터'!$B:$B,$G$1,'일별데이터'!$A:$A,$A22)*'계산기'!$C$11*(1-IF('계산기'!$H$5>0,INDEX('설정'!$G$4:$G$11,'계산기'!$H$5),0)/100),NA()) | F22: =IFERROR(C22-B22,NA()) | G22: =SUMIFS('일별데이터'!$E:$E,'일별데이터'!$B:$B,$G$1,'일별데이터'!$A:$A,$A22)
A23: =IFERROR(MAX('일별데이터'!$A:$A),TODAY())-19 | B23: =IFERROR(SUMIFS('일별데이터'!$I:$I,'일별데이터'!$B:$B,$G$1,'일별데이터'!$A:$A,$A23)/SUMIFS('일별데이터'!$E:$E,'일별데이터'!$B:$B,$G$1,'일별데이터'!$A:$A,$A23),NA()) | C23: =IFERROR(AVERAGEIFS('일별데이터'!$J:$J,'일별데이터'!$B:$B,$G$1,'일별데이터'!$A:$A,$A23)*'계산기'!$C$11,NA()) | D23: =IFERROR(AVERAGEIFS('일별데이터'!$N:$N,'일별데이터'!$B:$B,$G$1,'일별데이터'!$A:$A,$A23)*'계산기'!$C$11,NA()) | E23: =IFERROR(AVERAGEIFS('일별데이터'!$O:$O,'일별데이터'!$B:$B,$G$1,'일별데이터'!$A:$A,$A23)*'계산기'!$C$11*(1-IF('계산기'!$H$5>0,INDEX('설정'!$G$4:$G$11,'계산기'!$H$5),0)/100),NA()) | F23: =IFERROR(C23-B23,NA()) | G23: =SUMIFS('일별데이터'!$E:$E,'일별데이터'!$B:$B,$G$1,'일별데이터'!$A:$A,$A23)
A24: =IFERROR(MAX('일별데이터'!$A:$A),TODAY())-18 | B24: =IFERROR(SUMIFS('일별데이터'!$I:$I,'일별데이터'!$B:$B,$G$1,'일별데이터'!$A:$A,$A24)/SUMIFS('일별데이터'!$E:$E,'일별데이터'!$B:$B,$G$1,'일별데이터'!$A:$A,$A24),NA()) | C24: =IFERROR(AVERAGEIFS('일별데이터'!$J:$J,'일별데이터'!$B:$B,$G$1,'일별데이터'!$A:$A,$A24)*'계산기'!$C$11,NA()) | D24: =IFERROR(AVERAGEIFS('일별데이터'!$N:$N,'일별데이터'!$B:$B,$G$1,'일별데이터'!$A:$A,$A24)*'계산기'!$C$11,NA()) | E24: =IFERROR(AVERAGEIFS('일별데이터'!$O:$O,'일별데이터'!$B:$B,$G$1,'일별데이터'!$A:$A,$A24)*'계산기'!$C$11*(1-IF('계산기'!$H$5>0,INDEX('설정'!$G$4:$G$11,'계산기'!$H$5),0)/100),NA()) | F24: =IFERROR(C24-B24,NA()) | G24: =SUMIFS('일별데이터'!$E:$E,'일별데이터'!$B:$B,$G$1,'일별데이터'!$A:$A,$A24)
A25: =IFERROR(MAX('일별데이터'!$A:$A),TODAY())-17 | B25: =IFERROR(SUMIFS('일별데이터'!$I:$I,'일별데이터'!$B:$B,$G$1,'일별데이터'!$A:$A,$A25)/SUMIFS('일별데이터'!$E:$E,'일별데이터'!$B:$B,$G$1,'일별데이터'!$A:$A,$A25),NA()) | C25: =IFERROR(AVERAGEIFS('일별데이터'!$J:$J,'일별데이터'!$B:$B,$G$1,'일별데이터'!$A:$A,$A25)*'계산기'!$C$11,NA()) | D25: =IFERROR(AVERAGEIFS('일별데이터'!$N:$N,'일별데이터'!$B:$B,$G$1,'일별데이터'!$A:$A,$A25)*'계산기'!$C$11,NA()) | E25: =IFERROR(AVERAGEIFS('일별데이터'!$O:$O,'일별데이터'!$B:$B,$G$1,'일별데이터'!$A:$A,$A25)*'계산기'!$C$11*(1-IF('계산기'!$H$5>0,INDEX('설정'!$G$4:$G$11,'계산기'!$H$5),0)/100),NA()) | F25: =IFERROR(C25-B25,NA()) | G25: =SUMIFS('일별데이터'!$E:$E,'일별데이터'!$B:$B,$G$1,'일별데이터'!$A:$A,$A25)
A26: =IFERROR(MAX('일별데이터'!$A:$A),TODAY())-16 | B26: =IFERROR(SUMIFS('일별데이터'!$I:$I,'일별데이터'!$B:$B,$G$1,'일별데이터'!$A:$A,$A26)/SUMIFS('일별데이터'!$E:$E,'일별데이터'!$B:$B,$G$1,'일별데이터'!$A:$A,$A26),NA()) | C26: =IFERROR(AVERAGEIFS('일별데이터'!$J:$J,'일별데이터'!$B:$B,$G$1,'일별데이터'!$A:$A,$A26)*'계산기'!$C$11,NA()) | D26: =IFERROR(AVERAGEIFS('일별데이터'!$N:$N,'일별데이터'!$B:$B,$G$1,'일별데이터'!$A:$A,$A26)*'계산기'!$C$11,NA()) | E26: =IFERROR(AVERAGEIFS('일별데이터'!$O:$O,'일별데이터'!$B:$B,$G$1,'일별데이터'!$A:$A,$A26)*'계산기'!$C$11*(1-IF('계산기'!$H$5>0,INDEX('설정'!$G$4:$G$11,'계산기'!$H$5),0)/100),NA()) | F26: =IFERROR(C26-B26,NA()) | G26: =SUMIFS('일별데이터'!$E:$E,'일별데이터'!$B:$B,$G$1,'일별데이터'!$A:$A,$A26)
A27: =IFERROR(MAX('일별데이터'!$A:$A),TODAY())-15 | B27: =IFERROR(SUMIFS('일별데이터'!$I:$I,'일별데이터'!$B:$B,$G$1,'일별데이터'!$A:$A,$A27)/SUMIFS('일별데이터'!$E:$E,'일별데이터'!$B:$B,$G$1,'일별데이터'!$A:$A,$A27),NA()) | C27: =IFERROR(AVERAGEIFS('일별데이터'!$J:$J,'일별데이터'!$B:$B,$G$1,'일별데이터'!$A:$A,$A27)*'계산기'!$C$11,NA()) | D27: =IFERROR(AVERAGEIFS('일별데이터'!$N:$N,'일별데이터'!$B:$B,$G$1,'일별데이터'!$A:$A,$A27)*'계산기'!$C$11,NA()) | E27: =IFERROR(AVERAGEIFS('일별데이터'!$O:$O,'일별데이터'!$B:$B,$G$1,'일별데이터'!$A:$A,$A27)*'계산기'!$C$11*(1-IF('계산기'!$H$5>0,INDEX('설정'!$G$4:$G$11,'계산기'!$H$5),0)/100),NA()) | F27: =IFERROR(C27-B27,NA()) | G27: =SUMIFS('일별데이터'!$E:$E,'일별데이터'!$B:$B,$G$1,'일별데이터'!$A:$A,$A27)
A28: =IFERROR(MAX('일별데이터'!$A:$A),TODAY())-14 | B28: =IFERROR(SUMIFS('일별데이터'!$I:$I,'일별데이터'!$B:$B,$G$1,'일별데이터'!$A:$A,$A28)/SUMIFS('일별데이터'!$E:$E,'일별데이터'!$B:$B,$G$1,'일별데이터'!$A:$A,$A28),NA()) | C28: =IFERROR(AVERAGEIFS('일별데이터'!$J:$J,'일별데이터'!$B:$B,$G$1,'일별데이터'!$A:$A,$A28)*'계산기'!$C$11,NA()) | D28: =IFERROR(AVERAGEIFS('일별데이터'!$N:$N,'일별데이터'!$B:$B,$G$1,'일별데이터'!$A:$A,$A28)*'계산기'!$C$11,NA()) | E28: =IFERROR(AVERAGEIFS('일별데이터'!$O:$O,'일별데이터'!$B:$B,$G$1,'일별데이터'!$A:$A,$A28)*'계산기'!$C$11*(1-IF('계산기'!$H$5>0,INDEX('설정'!$G$4:$G$11,'계산기'!$H$5),0)/100),NA()) | F28: =IFERROR(C28-B28,NA()) | G28: =SUMIFS('일별데이터'!$E:$E,'일별데이터'!$B:$B,$G$1,'일별데이터'!$A:$A,$A28)
A29: =IFERROR(MAX('일별데이터'!$A:$A),TODAY())-13 | B29: =IFERROR(SUMIFS('일별데이터'!$I:$I,'일별데이터'!$B:$B,$G$1,'일별데이터'!$A:$A,$A29)/SUMIFS('일별데이터'!$E:$E,'일별데이터'!$B:$B,$G$1,'일별데이터'!$A:$A,$A29),NA()) | C29: =IFERROR(AVERAGEIFS('일별데이터'!$J:$J,'일별데이터'!$B:$B,$G$1,'일별데이터'!$A:$A,$A29)*'계산기'!$C$11,NA()) | D29: =IFERROR(AVERAGEIFS('일별데이터'!$N:$N,'일별데이터'!$B:$B,$G$1,'일별데이터'!$A:$A,$A29)*'계산기'!$C$11,NA()) | E29: =IFERROR(AVERAGEIFS('일별데이터'!$O:$O,'일별데이터'!$B:$B,$G$1,'일별데이터'!$A:$A,$A29)*'계산기'!$C$11*(1-IF('계산기'!$H$5>0,INDEX('설정'!$G$4:$G$11,'계산기'!$H$5),0)/100),NA()) | F29: =IFERROR(C29-B29,NA()) | G29: =SUMIFS('일별데이터'!$E:$E,'일별데이터'!$B:$B,$G$1,'일별데이터'!$A:$A,$A29)
A30: =IFERROR(MAX('일별데이터'!$A:$A),TODAY())-12 | B30: =IFERROR(SUMIFS('일별데이터'!$I:$I,'일별데이터'!$B:$B,$G$1,'일별데이터'!$A:$A,$A30)/SUMIFS('일별데이터'!$E:$E,'일별데이터'!$B:$B,$G$1,'일별데이터'!$A:$A,$A30),NA()) | C30: =IFERROR(AVERAGEIFS('일별데이터'!$J:$J,'일별데이터'!$B:$B,$G$1,'일별데이터'!$A:$A,$A30)*'계산기'!$C$11,NA()) | D30: =IFERROR(AVERAGEIFS('일별데이터'!$N:$N,'일별데이터'!$B:$B,$G$1,'일별데이터'!$A:$A,$A30)*'계산기'!$C$11,NA()) | E30: =IFERROR(AVERAGEIFS('일별데이터'!$O:$O,'일별데이터'!$B:$B,$G$1,'일별데이터'!$A:$A,$A30)*'계산기'!$C$11*(1-IF('계산기'!$H$5>0,INDEX('설정'!$G$4:$G$11,'계산기'!$H$5),0)/100),NA()) | F30: =IFERROR(C30-B30,NA()) | G30: =SUMIFS('일별데이터'!$E:$E,'일별데이터'!$B:$B,$G$1,'일별데이터'!$A:$A,$A30)
A31: =IFERROR(MAX('일별데이터'!$A:$A),TODAY())-11 | B31: =IFERROR(SUMIFS('일별데이터'!$I:$I,'일별데이터'!$B:$B,$G$1,'일별데이터'!$A:$A,$A31)/SUMIFS('일별데이터'!$E:$E,'일별데이터'!$B:$B,$G$1,'일별데이터'!$A:$A,$A31),NA()) | C31: =IFERROR(AVERAGEIFS('일별데이터'!$J:$J,'일별데이터'!$B:$B,$G$1,'일별데이터'!$A:$A,$A31)*'계산기'!$C$11,NA()) | D31: =IFERROR(AVERAGEIFS('일별데이터'!$N:$N,'일별데이터'!$B:$B,$G$1,'일별데이터'!$A:$A,$A31)*'계산기'!$C$11,NA()) | E31: =IFERROR(AVERAGEIFS('일별데이터'!$O:$O,'일별데이터'!$B:$B,$G$1,'일별데이터'!$A:$A,$A31)*'계산기'!$C$11*(1-IF('계산기'!$H$5>0,INDEX('설정'!$G$4:$G$11,'계산기'!$H$5),0)/100),NA()) | F31: =IFERROR(C31-B31,NA()) | G31: =SUMIFS('일별데이터'!$E:$E,'일별데이터'!$B:$B,$G$1,'일별데이터'!$A:$A,$A31)
A32: =IFERROR(MAX('일별데이터'!$A:$A),TODAY())-10 | B32: =IFERROR(SUMIFS('일별데이터'!$I:$I,'일별데이터'!$B:$B,$G$1,'일별데이터'!$A:$A,$A32)/SUMIFS('일별데이터'!$E:$E,'일별데이터'!$B:$B,$G$1,'일별데이터'!$A:$A,$A32),NA()) | C32: =IFERROR(AVERAGEIFS('일별데이터'!$J:$J,'일별데이터'!$B:$B,$G$1,'일별데이터'!$A:$A,$A32)*'계산기'!$C$11,NA()) | D32: =IFERROR(AVERAGEIFS('일별데이터'!$N:$N,'일별데이터'!$B:$B,$G$1,'일별데이터'!$A:$A,$A32)*'계산기'!$C$11,NA()) | E32: =IFERROR(AVERAGEIFS('일별데이터'!$O:$O,'일별데이터'!$B:$B,$G$1,'일별데이터'!$A:$A,$A32)*'계산기'!$C$11*(1-IF('계산기'!$H$5>0,INDEX('설정'!$G$4:$G$11,'계산기'!$H$5),0)/100),NA()) | F32: =IFERROR(C32-B32,NA()) | G32: =SUMIFS('일별데이터'!$E:$E,'일별데이터'!$B:$B,$G$1,'일별데이터'!$A:$A,$A32)
A33: =IFERROR(MAX('일별데이터'!$A:$A),TODAY())-9 | B33: =IFERROR(SUMIFS('일별데이터'!$I:$I,'일별데이터'!$B:$B,$G$1,'일별데이터'!$A:$A,$A33)/SUMIFS('일별데이터'!$E:$E,'일별데이터'!$B:$B,$G$1,'일별데이터'!$A:$A,$A33),NA()) | C33: =IFERROR(AVERAGEIFS('일별데이터'!$J:$J,'일별데이터'!$B:$B,$G$1,'일별데이터'!$A:$A,$A33)*'계산기'!$C$11,NA()) | D33: =IFERROR(AVERAGEIFS('일별데이터'!$N:$N,'일별데이터'!$B:$B,$G$1,'일별데이터'!$A:$A,$A33)*'계산기'!$C$11,NA()) | E33: =IFERROR(AVERAGEIFS('일별데이터'!$O:$O,'일별데이터'!$B:$B,$G$1,'일별데이터'!$A:$A,$A33)*'계산기'!$C$11*(1-IF('계산기'!$H$5>0,INDEX('설정'!$G$4:$G$11,'계산기'!$H$5),0)/100),NA()) | F33: =IFERROR(C33-B33,NA()) | G33: =SUMIFS('일별데이터'!$E:$E,'일별데이터'!$B:$B,$G$1,'일별데이터'!$A:$A,$A33)
A34: =IFERROR(MAX('일별데이터'!$A:$A),TODAY())-8 | B34: =IFERROR(SUMIFS('일별데이터'!$I:$I,'일별데이터'!$B:$B,$G$1,'일별데이터'!$A:$A,$A34)/SUMIFS('일별데이터'!$E:$E,'일별데이터'!$B:$B,$G$1,'일별데이터'!$A:$A,$A34),NA()) | C34: =IFERROR(AVERAGEIFS('일별데이터'!$J:$J,'일별데이터'!$B:$B,$G$1,'일별데이터'!$A:$A,$A34)*'계산기'!$C$11,NA()) | D34: =IFERROR(AVERAGEIFS('일별데이터'!$N:$N,'일별데이터'!$B:$B,$G$1,'일별데이터'!$A:$A,$A34)*'계산기'!$C$11,NA()) | E34: =IFERROR(AVERAGEIFS('일별데이터'!$O:$O,'일별데이터'!$B:$B,$G$1,'일별데이터'!$A:$A,$A34)*'계산기'!$C$11*(1-IF('계산기'!$H$5>0,INDEX('설정'!$G$4:$G$11,'계산기'!$H$5),0)/100),NA()) | F34: =IFERROR(C34-B34,NA()) | G34: =SUMIFS('일별데이터'!$E:$E,'일별데이터'!$B:$B,$G$1,'일별데이터'!$A:$A,$A34)
A35: =IFERROR(MAX('일별데이터'!$A:$A),TODAY())-7 | B35: =IFERROR(SUMIFS('일별데이터'!$I:$I,'일별데이터'!$B:$B,$G$1,'일별데이터'!$A:$A,$A35)/SUMIFS('일별데이터'!$E:$E,'일별데이터'!$B:$B,$G$1,'일별데이터'!$A:$A,$A35),NA()) | C35: =IFERROR(AVERAGEIFS('일별데이터'!$J:$J,'일별데이터'!$B:$B,$G$1,'일별데이터'!$A:$A,$A35)*'계산기'!$C$11,NA()) | D35: =IFERROR(AVERAGEIFS('일별데이터'!$N:$N,'일별데이터'!$B:$B,$G$1,'일별데이터'!$A:$A,$A35)*'계산기'!$C$11,NA()) | E35: =IFERROR(AVERAGEIFS('일별데이터'!$O:$O,'일별데이터'!$B:$B,$G$1,'일별데이터'!$A:$A,$A35)*'계산기'!$C$11*(1-IF('계산기'!$H$5>0,INDEX('설정'!$G$4:$G$11,'계산기'!$H$5),0)/100),NA()) | F35: =IFERROR(C35-B35,NA()) | G35: =SUMIFS('일별데이터'!$E:$E,'일별데이터'!$B:$B,$G$1,'일별데이터'!$A:$A,$A35)
A36: =IFERROR(MAX('일별데이터'!$A:$A),TODAY())-6 | B36: =IFERROR(SUMIFS('일별데이터'!$I:$I,'일별데이터'!$B:$B,$G$1,'일별데이터'!$A:$A,$A36)/SUMIFS('일별데이터'!$E:$E,'일별데이터'!$B:$B,$G$1,'일별데이터'!$A:$A,$A36),NA()) | C36: =IFERROR(AVERAGEIFS('일별데이터'!$J:$J,'일별데이터'!$B:$B,$G$1,'일별데이터'!$A:$A,$A36)*'계산기'!$C$11,NA()) | D36: =IFERROR(AVERAGEIFS('일별데이터'!$N:$N,'일별데이터'!$B:$B,$G$1,'일별데이터'!$A:$A,$A36)*'계산기'!$C$11,NA()) | E36: =IFERROR(AVERAGEIFS('일별데이터'!$O:$O,'일별데이터'!$B:$B,$G$1,'일별데이터'!$A:$A,$A36)*'계산기'!$C$11*(1-IF('계산기'!$H$5>0,INDEX('설정'!$G$4:$G$11,'계산기'!$H$5),0)/100),NA()) | F36: =IFERROR(C36-B36,NA()) | G36: =SUMIFS('일별데이터'!$E:$E,'일별데이터'!$B:$B,$G$1,'일별데이터'!$A:$A,$A36)
A37: =IFERROR(MAX('일별데이터'!$A:$A),TODAY())-5 | B37: =IFERROR(SUMIFS('일별데이터'!$I:$I,'일별데이터'!$B:$B,$G$1,'일별데이터'!$A:$A,$A37)/SUMIFS('일별데이터'!$E:$E,'일별데이터'!$B:$B,$G$1,'일별데이터'!$A:$A,$A37),NA()) | C37: =IFERROR(AVERAGEIFS('일별데이터'!$J:$J,'일별데이터'!$B:$B,$G$1,'일별데이터'!$A:$A,$A37)*'계산기'!$C$11,NA()) | D37: =IFERROR(AVERAGEIFS('일별데이터'!$N:$N,'일별데이터'!$B:$B,$G$1,'일별데이터'!$A:$A,$A37)*'계산기'!$C$11,NA()) | E37: =IFERROR(AVERAGEIFS('일별데이터'!$O:$O,'일별데이터'!$B:$B,$G$1,'일별데이터'!$A:$A,$A37)*'계산기'!$C$11*(1-IF('계산기'!$H$5>0,INDEX('설정'!$G$4:$G$11,'계산기'!$H$5),0)/100),NA()) | F37: =IFERROR(C37-B37,NA()) | G37: =SUMIFS('일별데이터'!$E:$E,'일별데이터'!$B:$B,$G$1,'일별데이터'!$A:$A,$A37)
A38: =IFERROR(MAX('일별데이터'!$A:$A),TODAY())-4 | B38: =IFERROR(SUMIFS('일별데이터'!$I:$I,'일별데이터'!$B:$B,$G$1,'일별데이터'!$A:$A,$A38)/SUMIFS('일별데이터'!$E:$E,'일별데이터'!$B:$B,$G$1,'일별데이터'!$A:$A,$A38),NA()) | C38: =IFERROR(AVERAGEIFS('일별데이터'!$J:$J,'일별데이터'!$B:$B,$G$1,'일별데이터'!$A:$A,$A38)*'계산기'!$C$11,NA()) | D38: =IFERROR(AVERAGEIFS('일별데이터'!$N:$N,'일별데이터'!$B:$B,$G$1,'일별데이터'!$A:$A,$A38)*'계산기'!$C$11,NA()) | E38: =IFERROR(AVERAGEIFS('일별데이터'!$O:$O,'일별데이터'!$B:$B,$G$1,'일별데이터'!$A:$A,$A38)*'계산기'!$C$11*(1-IF('계산기'!$H$5>0,INDEX('설정'!$G$4:$G$11,'계산기'!$H$5),0)/100),NA()) | F38: =IFERROR(C38-B38,NA()) | G38: =SUMIFS('일별데이터'!$E:$E,'일별데이터'!$B:$B,$G$1,'일별데이터'!$A:$A,$A38)
A39: =IFERROR(MAX('일별데이터'!$A:$A),TODAY())-3 | B39: =IFERROR(SUMIFS('일별데이터'!$I:$I,'일별데이터'!$B:$B,$G$1,'일별데이터'!$A:$A,$A39)/SUMIFS('일별데이터'!$E:$E,'일별데이터'!$B:$B,$G$1,'일별데이터'!$A:$A,$A39),NA()) | C39: =IFERROR(AVERAGEIFS('일별데이터'!$J:$J,'일별데이터'!$B:$B,$G$1,'일별데이터'!$A:$A,$A39)*'계산기'!$C$11,NA()) | D39: =IFERROR(AVERAGEIFS('일별데이터'!$N:$N,'일별데이터'!$B:$B,$G$1,'일별데이터'!$A:$A,$A39)*'계산기'!$C$11,NA()) | E39: =IFERROR(AVERAGEIFS('일별데이터'!$O:$O,'일별데이터'!$B:$B,$G$1,'일별데이터'!$A:$A,$A39)*'계산기'!$C$11*(1-IF('계산기'!$H$5>0,INDEX('설정'!$G$4:$G$11,'계산기'!$H$5),0)/100),NA()) | F39: =IFERROR(C39-B39,NA()) | G39: =SUMIFS('일별데이터'!$E:$E,'일별데이터'!$B:$B,$G$1,'일별데이터'!$A:$A,$A39)
A40: =IFERROR(MAX('일별데이터'!$A:$A),TODAY())-2 | B40: =IFERROR(SUMIFS('일별데이터'!$I:$I,'일별데이터'!$B:$B,$G$1,'일별데이터'!$A:$A,$A40)/SUMIFS('일별데이터'!$E:$E,'일별데이터'!$B:$B,$G$1,'일별데이터'!$A:$A,$A40),NA()) | C40: =IFERROR(AVERAGEIFS('일별데이터'!$J:$J,'일별데이터'!$B:$B,$G$1,'일별데이터'!$A:$A,$A40)*'계산기'!$C$11,NA()) | D40: =IFERROR(AVERAGEIFS('일별데이터'!$N:$N,'일별데이터'!$B:$B,$G$1,'일별데이터'!$A:$A,$A40)*'계산기'!$C$11,NA()) | E40: =IFERROR(AVERAGEIFS('일별데이터'!$O:$O,'일별데이터'!$B:$B,$G$1,'일별데이터'!$A:$A,$A40)*'계산기'!$C$11*(1-IF('계산기'!$H$5>0,INDEX('설정'!$G$4:$G$11,'계산기'!$H$5),0)/100),NA()) | F40: =IFERROR(C40-B40,NA()) | G40: =SUMIFS('일별데이터'!$E:$E,'일별데이터'!$B:$B,$G$1,'일별데이터'!$A:$A,$A40)
...

Sheet 설정
A1: 마진 계산 설정 — 판매 채널별 비용·상한 기준
A2: 노란 칸을 고치면 계산기·품목요약·그래프가 다시 계산됩니다. (앱 화면의 설정은 서버에 저장되고, 이 파일을 고쳐도 서버에는 반영되지 않습니다)
A3: 채널 | B3: 수수료율(%) | C3: 택배비(원/박스) | D3: 포장비(원/박스) | E3: 기타 비용(원/박스) | F3: 상한 기준(소매|가락) | G3: 소매 대비 할인(%) | H3: 가락 대비 가산(%) | I3: 최소 마진(%)
A13: 원가 기준 | D13: 최근 = 최근 경매일 가중평균 · 7일평균 = 최근 7일 가중평균 · 7일최고 = 최근 7일 중 가장 비싼 날
A15: 자료 기간 | B15: -
A16: 만든 시각 | B16: -
A17: 시세 자료 | B17: -
A19: 계산식
A20: 원가 C = 원가 기준에 따른 서원 낙찰 단가(박스당)
A21: 부대비 F = 택배비 + 포장비 + 기타 비용, 수수료율 r
A22: 손익분기가 = (C + F) ÷ (1 − r)
A23: 최소 마진가 = 손익분기가 × (1 + 최소 마진%)
A24: 상한가 = 소매 기준: 지역 소매 kg당 가운데값 × 박스kg × (1 − 소매 대비 할인%) / 가락 기준: 가락시장 7일 kg당 평균 × 박스kg × (1 + 가락 대비 가산%) (자료가 없으면 다른 기준으로 대신)
A25: 최대 마진 = 상한가 × (1 − r) − C − F, 마진율 = 최대 마진 ÷ 상한가, 권장가 = (최소 마진가 + 상한가) ÷ 2

Sheet 일별데이터
A1: 날짜 | B1: 품목 | C1: 등급 | D1: 박스kg | E1: 서원 낙찰 수량 | F1: 서원 평균 단가(박스) | G1: 서원 최저 단가 | H1: 서원 최고 단가 | I1: 서원 낙찰 금액 | J1: 가락 kg당 평균 | K1: 가락 kg당 최저 | L1: 가락 kg당 최고 | M1: 가락 거래량 | N1: 전국 kg당 평균 | O1: 소매 kg당(가운데) | P1: 가락 박스 환산 | Q1: 가락보다 싸게 산 금액 | R1: 가락 시세 출처

Sheet 낙찰원장
A1: 경매일 | B1: 시장 | C1: 번호 | D1: 품목(사이트) | E1: 품목(정리) | F1: 생산자 | G1: 규격 | H1: 등급 | I1: 박스kg | J1: 수량 | K1: 단가 | L1: 금액

Sheet 품목DB
A1: 품목 | B1: 품목군 | C1: 등급 | D1: 박스kg (수량) | E1: 처음 낙찰 | F1: 마지막 낙찰 | G1: 낙찰한 날 수 | H1: 총 수량 | I1: 총 금액 | J1: 평균 단가(박스) | K1: 서울청과 수량 | L1: 동화청과 수량 | M1: 가락 시세 모음
